[2024-05-02T17:25:29.504+0000] {local_task_job_runner.py:120} INFO - ::group::Pre task execution logs
[2024-05-02T17:25:29.532+0000] {taskinstance.py:2073} INFO - Dependencies all met for dep_context=non-requeueable deps ti=<TaskInstance: wikipedia_flow.transform_wikipedia_data manual__2024-05-02T17:25:21.116814+00:00 [queued]>
[2024-05-02T17:25:29.539+0000] {taskinstance.py:2073} INFO - Dependencies all met for dep_context=requeueable deps ti=<TaskInstance: wikipedia_flow.transform_wikipedia_data manual__2024-05-02T17:25:21.116814+00:00 [queued]>
[2024-05-02T17:25:29.539+0000] {taskinstance.py:2303} INFO - Starting attempt 1 of 1
[2024-05-02T17:25:29.550+0000] {taskinstance.py:2327} INFO - Executing <Task(PythonOperator): transform_wikipedia_data> on 2024-05-02 17:25:21.116814+00:00
[2024-05-02T17:25:29.554+0000] {standard_task_runner.py:63} INFO - Started process 880 to run task
[2024-05-02T17:25:29.556+0000] {standard_task_runner.py:90} INFO - Running: ['***', 'tasks', 'run', 'wikipedia_flow', 'transform_wikipedia_data', 'manual__2024-05-02T17:25:21.116814+00:00', '--job-id', '6', '--raw', '--subdir', 'DAGS_FOLDER/wikipedia_flow.py', '--cfg-path', '/tmp/tmptkzky087']
[2024-05-02T17:25:29.557+0000] {standard_task_runner.py:91} INFO - Job 6: Subtask transform_wikipedia_data
[2024-05-02T17:25:29.602+0000] {task_command.py:426} INFO - Running <TaskInstance: wikipedia_flow.transform_wikipedia_data manual__2024-05-02T17:25:21.116814+00:00 [running]> on host ac73955389ba
[2024-05-02T17:25:29.767+0000] {taskinstance.py:2644} INFO - Exporting env vars: AIRFLOW_CTX_DAG_OWNER='Minh Tran' AIRFLOW_CTX_DAG_ID='wikipedia_flow' AIRFLOW_CTX_TASK_ID='transform_wikipedia_data' AIRFLOW_CTX_EXECUTION_DATE='2024-05-02T17:25:21.116814+00:00' AIRFLOW_CTX_TRY_NUMBER='1' AIRFLOW_CTX_DAG_RUN_ID='manual__2024-05-02T17:25:21.116814+00:00'
[2024-05-02T17:25:29.768+0000] {taskinstance.py:430} INFO - ::endgroup::
[2024-05-02T17:28:00.684+0000] {taskinstance.py:441} INFO - ::group::Post task execution logs
[2024-05-02T17:28:00.686+0000] {taskinstance.py:2890} ERROR - Task failed with exception
Traceback (most recent call last):
  File "/home/airflow/.local/lib/python3.9/site-packages/urllib3/connectionpool.py", line 537, in _make_request
    response = conn.getresponse()
  File "/home/airflow/.local/lib/python3.9/site-packages/urllib3/connection.py", line 466, in getresponse
    httplib_response = super().getresponse()
  File "/usr/local/lib/python3.9/http/client.py", line 1377, in getresponse
    response.begin()
  File "/usr/local/lib/python3.9/http/client.py", line 320, in begin
    version, status, reason = self._read_status()
  File "/usr/local/lib/python3.9/http/client.py", line 281, in _read_status
    line = str(self.fp.readline(_MAXLINE + 1), "iso-8859-1")
  File "/usr/local/lib/python3.9/socket.py", line 704, in readinto
    return self._sock.recv_into(b)
  File "/usr/local/lib/python3.9/ssl.py", line 1242, in recv_into
    return self.read(nbytes, buffer)
  File "/usr/local/lib/python3.9/ssl.py", line 1100, in read
    return self._sslobj.read(len, buffer)
socket.timeout: The read operation timed out

The above exception was the direct cause of the following exception:

Traceback (most recent call last):
  File "/home/airflow/.local/lib/python3.9/site-packages/requests/adapters.py", line 486, in send
    resp = conn.urlopen(
  File "/home/airflow/.local/lib/python3.9/site-packages/urllib3/connectionpool.py", line 847, in urlopen
    retries = retries.increment(
  File "/home/airflow/.local/lib/python3.9/site-packages/urllib3/util/retry.py", line 470, in increment
    raise reraise(type(error), error, _stacktrace)
  File "/home/airflow/.local/lib/python3.9/site-packages/urllib3/util/util.py", line 39, in reraise
    raise value
  File "/home/airflow/.local/lib/python3.9/site-packages/urllib3/connectionpool.py", line 793, in urlopen
    response = self._make_request(
  File "/home/airflow/.local/lib/python3.9/site-packages/urllib3/connectionpool.py", line 539, in _make_request
    self._raise_timeout(err=e, url=url, timeout_value=read_timeout)
  File "/home/airflow/.local/lib/python3.9/site-packages/urllib3/connectionpool.py", line 370, in _raise_timeout
    raise ReadTimeoutError(
urllib3.exceptions.ReadTimeoutError: HTTPSConnectionPool(host='nominatim.openstreetmap.org', port=443): Read timed out. (read timeout=20)

During handling of the above exception, another exception occurred:

Traceback (most recent call last):
  File "/home/airflow/.local/lib/python3.9/site-packages/airflow/models/taskinstance.py", line 465, in _execute_task
    result = _execute_callable(context=context, **execute_callable_kwargs)
  File "/home/airflow/.local/lib/python3.9/site-packages/airflow/models/taskinstance.py", line 432, in _execute_callable
    return execute_callable(context=context, **execute_callable_kwargs)
  File "/home/airflow/.local/lib/python3.9/site-packages/airflow/models/baseoperator.py", line 400, in wrapper
    return func(self, *args, **kwargs)
  File "/home/airflow/.local/lib/python3.9/site-packages/airflow/operators/python.py", line 235, in execute
    return_value = self.execute_callable()
  File "/home/airflow/.local/lib/python3.9/site-packages/airflow/operators/python.py", line 252, in execute_callable
    return self.python_callable(*self.op_args, **self.op_kwargs)
  File "/opt/airflow/pipelines/wikipedia_pipeline.py", line 102, in transform_wikipedia_data
    stadiums_df['location'] = stadiums_df.apply(lambda x: get_lat_long(x['country'], x['stadium']), axis = 1)
  File "/home/airflow/.local/lib/python3.9/site-packages/pandas/core/frame.py", line 10374, in apply
    return op.apply().__finalize__(self, method="apply")
  File "/home/airflow/.local/lib/python3.9/site-packages/pandas/core/apply.py", line 916, in apply
    return self.apply_standard()
  File "/home/airflow/.local/lib/python3.9/site-packages/pandas/core/apply.py", line 1063, in apply_standard
    results, res_index = self.apply_series_generator()
  File "/home/airflow/.local/lib/python3.9/site-packages/pandas/core/apply.py", line 1081, in apply_series_generator
    results[i] = self.func(v, *self.args, **self.kwargs)
  File "/opt/airflow/pipelines/wikipedia_pipeline.py", line 102, in <lambda>
    stadiums_df['location'] = stadiums_df.apply(lambda x: get_lat_long(x['country'], x['stadium']), axis = 1)
  File "/opt/airflow/pipelines/wikipedia_pipeline.py", line 83, in get_lat_long
    response = requests.get(url, headers=headers, timeout=20)
  File "/home/airflow/.local/lib/python3.9/site-packages/requests/api.py", line 73, in get
    return request("get", url, params=params, **kwargs)
  File "/home/airflow/.local/lib/python3.9/site-packages/requests/api.py", line 59, in request
    return session.request(method=method, url=url, **kwargs)
  File "/home/airflow/.local/lib/python3.9/site-packages/requests/sessions.py", line 589, in request
    resp = self.send(prep, **send_kwargs)
  File "/home/airflow/.local/lib/python3.9/site-packages/requests/sessions.py", line 703, in send
    r = adapter.send(request, **kwargs)
  File "/home/airflow/.local/lib/python3.9/site-packages/requests/adapters.py", line 532, in send
    raise ReadTimeout(e, request=request)
requests.exceptions.ReadTimeout: HTTPSConnectionPool(host='nominatim.openstreetmap.org', port=443): Read timed out. (read timeout=20)
[2024-05-02T17:28:00.701+0000] {taskinstance.py:1205} INFO - Marking task as FAILED. dag_id=wikipedia_flow, task_id=transform_wikipedia_data, execution_date=20240502T172521, start_date=20240502T172529, end_date=20240502T172800
[2024-05-02T17:28:00.709+0000] {standard_task_runner.py:110} ERROR - Failed to execute job 6 for task transform_wikipedia_data (HTTPSConnectionPool(host='nominatim.openstreetmap.org', port=443): Read timed out. (read timeout=20); 880)
[2024-05-02T17:28:00.728+0000] {local_task_job_runner.py:240} INFO - Task exited with return code 1
[2024-05-02T17:28:00.820+0000] {taskinstance.py:3482} INFO - 0 downstream tasks scheduled from follow-on schedule check
[2024-05-02T17:28:00.828+0000] {local_task_job_runner.py:222} INFO - ::endgroup::
