[2024-05-01T15:49:39.852+0000] {local_task_job_runner.py:120} INFO - ::group::Pre task execution logs
[2024-05-01T15:49:39.880+0000] {taskinstance.py:2073} INFO - Dependencies all met for dep_context=non-requeueable deps ti=<TaskInstance: wikipedia_flow.transform_wikipedia_data manual__2024-05-01T15:49:28.840838+00:00 [queued]>
[2024-05-01T15:49:39.889+0000] {taskinstance.py:2073} INFO - Dependencies all met for dep_context=requeueable deps ti=<TaskInstance: wikipedia_flow.transform_wikipedia_data manual__2024-05-01T15:49:28.840838+00:00 [queued]>
[2024-05-01T15:49:39.889+0000] {taskinstance.py:2303} INFO - Starting attempt 1 of 1
[2024-05-01T15:49:39.901+0000] {taskinstance.py:2327} INFO - Executing <Task(PythonOperator): transform_wikipedia_data> on 2024-05-01 15:49:28.840838+00:00
[2024-05-01T15:49:39.906+0000] {standard_task_runner.py:63} INFO - Started process 3256 to run task
[2024-05-01T15:49:39.908+0000] {standard_task_runner.py:90} INFO - Running: ['***', 'tasks', 'run', 'wikipedia_flow', 'transform_wikipedia_data', 'manual__2024-05-01T15:49:28.840838+00:00', '--job-id', '14', '--raw', '--subdir', 'DAGS_FOLDER/wikipedia_flow.py', '--cfg-path', '/tmp/tmp2o5hkz77']
[2024-05-01T15:49:39.910+0000] {standard_task_runner.py:91} INFO - Job 14: Subtask transform_wikipedia_data
[2024-05-01T15:49:39.954+0000] {task_command.py:426} INFO - Running <TaskInstance: wikipedia_flow.transform_wikipedia_data manual__2024-05-01T15:49:28.840838+00:00 [running]> on host ab8381b78bd9
[2024-05-01T15:49:40.116+0000] {taskinstance.py:2644} INFO - Exporting env vars: AIRFLOW_CTX_DAG_OWNER='Minh Tran' AIRFLOW_CTX_DAG_ID='wikipedia_flow' AIRFLOW_CTX_TASK_ID='transform_wikipedia_data' AIRFLOW_CTX_EXECUTION_DATE='2024-05-01T15:49:28.840838+00:00' AIRFLOW_CTX_TRY_NUMBER='1' AIRFLOW_CTX_DAG_RUN_ID='manual__2024-05-01T15:49:28.840838+00:00'
[2024-05-01T15:49:40.117+0000] {taskinstance.py:430} INFO - ::endgroup::
[2024-05-01T15:49:43.032+0000] {connectionpool.py:874} WARNING - Retrying (Retry(total=1, connect=None, read=None, redirect=None, status=None)) after connection broken by 'ReadTimeoutError("HTTPSConnectionPool(host='nominatim.openstreetmap.org', port=443): Read timed out. (read timeout=1)")': /search?q=Rungrado+1st+of+May+Stadium%2C+North+Korea&format=json&limit=1
[2024-05-01T15:49:55.712+0000] {connectionpool.py:874} WARNING - Retrying (Retry(total=1, connect=None, read=None, redirect=None, status=None)) after connection broken by 'NewConnectionError('<urllib3.connection.HTTPSConnection object at 0x78e337864640>: Failed to establish a new connection: [Errno 101] Network is unreachable')': /search?q=Estadio+Azteca%2C+Mexico&format=json&limit=1
[2024-05-01T15:49:57.131+0000] {connectionpool.py:874} WARNING - Retrying (Retry(total=0, connect=None, read=None, redirect=None, status=None)) after connection broken by 'ReadTimeoutError("HTTPSConnectionPool(host='nominatim.openstreetmap.org', port=443): Read timed out. (read timeout=1)")': /search?q=Estadio+Azteca%2C+Mexico&format=json&limit=1
[2024-05-01T15:50:07.077+0000] {connectionpool.py:874} WARNING - Retrying (Retry(total=1, connect=None, read=None, redirect=None, status=None)) after connection broken by 'NewConnectionError('<urllib3.connection.HTTPSConnection object at 0x78e3378170d0>: Failed to establish a new connection: [Errno 101] Network is unreachable')': /search?q=Cotton+Bowl+Stadium%2C+United+States&format=json&limit=1
[2024-05-01T15:50:17.318+0000] {connectionpool.py:874} WARNING - Retrying (Retry(total=1, connect=None, read=None, redirect=None, status=None)) after connection broken by 'NewConnectionError('<urllib3.connection.HTTPSConnection object at 0x78e3378221f0>: Failed to establish a new connection: [Errno 101] Network is unreachable')': /search?q=Borg+el-Arab+Stadium%2C+Egypt&format=json&limit=1
[2024-05-01T15:50:25.710+0000] {connectionpool.py:874} WARNING - Retrying (Retry(total=1, connect=None, read=None, redirect=None, status=None)) after connection broken by 'ReadTimeoutError("HTTPSConnectionPool(host='nominatim.openstreetmap.org', port=443): Read timed out. (read timeout=1)")': /search?q=Stadium+Australia%2C+Australia&format=json&limit=1
[2024-05-01T15:50:29.934+0000] {connectionpool.py:874} WARNING - Retrying (Retry(total=1, connect=None, read=None, redirect=None, status=None)) after connection broken by 'ReadTimeoutError("HTTPSConnectionPool(host='nominatim.openstreetmap.org', port=443): Read timed out. (read timeout=1)")': /search?q=MetLife+Stadium%2C+United+States&format=json&limit=1
[2024-05-01T15:50:38.638+0000] {connectionpool.py:874} WARNING - Retrying (Retry(total=1, connect=None, read=None, redirect=None, status=None)) after connection broken by 'ReadTimeoutError("HTTPSConnectionPool(host='nominatim.openstreetmap.org', port=443): Read timed out. (read timeout=1)")': /search?q=Lambeau+Field%2C+United+States&format=json&limit=1
[2024-05-01T15:50:45.067+0000] {connectionpool.py:874} WARNING - Retrying (Retry(total=1, connect=None, read=None, redirect=None, status=None)) after connection broken by 'NewConnectionError('<urllib3.connection.HTTPSConnection object at 0x78e337817700>: Failed to establish a new connection: [Errno 101] Network is unreachable')': /search?q=Stade+de+France%2C+France&format=json&limit=1
[2024-05-01T15:50:46.070+0000] {connectionpool.py:874} WARNING - Retrying (Retry(total=0, connect=None, read=None, redirect=None, status=None)) after connection broken by 'NewConnectionError('<urllib3.connection.HTTPSConnection object at 0x78e337822bb0>: Failed to establish a new connection: [Errno 101] Network is unreachable')': /search?q=Stade+de+France%2C+France&format=json&limit=1
[2024-05-01T15:50:50.517+0000] {connectionpool.py:874} WARNING - Retrying (Retry(total=1, connect=None, read=None, redirect=None, status=None)) after connection broken by 'ReadTimeoutError("HTTPSConnectionPool(host='nominatim.openstreetmap.org', port=443): Read timed out. (read timeout=1)")': /search?q=Grand+Sports+Arena+of+the+Luzhniki+Olympic+Complex%2C+Russia&format=json&limit=1
[2024-05-01T15:50:53.813+0000] {connectionpool.py:874} WARNING - Retrying (Retry(total=1, connect=None, read=None, redirect=None, status=None)) after connection broken by 'NewConnectionError('<urllib3.connection.HTTPSConnection object at 0x78e337864bb0>: Failed to establish a new connection: [Errno 101] Network is unreachable')': /search?q=Shah+Alam+Stadium%2C+Malaysia&format=json&limit=1
[2024-05-01T15:50:54.816+0000] {connectionpool.py:874} WARNING - Retrying (Retry(total=0, connect=None, read=None, redirect=None, status=None)) after connection broken by 'NewConnectionError('<urllib3.connection.HTTPSConnection object at 0x78e337829160>: Failed to establish a new connection: [Errno 101] Network is unreachable')': /search?q=Shah+Alam+Stadium%2C+Malaysia&format=json&limit=1
[2024-05-01T15:50:58.073+0000] {connectionpool.py:874} WARNING - Retrying (Retry(total=1, connect=None, read=None, redirect=None, status=None)) after connection broken by 'NewConnectionError('<urllib3.connection.HTTPSConnection object at 0x78e3378175b0>: Failed to establish a new connection: [Errno 101] Network is unreachable')': /search?q=Estadio+Monumental%2C+Peru&format=json&limit=1
[2024-05-01T15:50:59.834+0000] {connectionpool.py:874} WARNING - Retrying (Retry(total=0, connect=None, read=None, redirect=None, status=None)) after connection broken by 'ReadTimeoutError("HTTPSConnectionPool(host='nominatim.openstreetmap.org', port=443): Read timed out. (read timeout=1)")': /search?q=Estadio+Monumental%2C+Peru&format=json&limit=1
[2024-05-01T15:51:04.136+0000] {connectionpool.py:874} WARNING - Retrying (Retry(total=1, connect=None, read=None, redirect=None, status=None)) after connection broken by 'ReadTimeoutError("HTTPSConnectionPool(host='nominatim.openstreetmap.org', port=443): Read timed out. (read timeout=1)")': /search?q=Stadio+Giuseppe+Meazza%2C+Italy&format=json&limit=1
[2024-05-01T15:51:05.139+0000] {connectionpool.py:874} WARNING - Retrying (Retry(total=0, connect=None, read=None, redirect=None, status=None)) after connection broken by 'NewConnectionError('<urllib3.connection.HTTPSConnection object at 0x78e337864700>: Failed to establish a new connection: [Errno 101] Network is unreachable')': /search?q=Stadio+Giuseppe+Meazza%2C+Italy&format=json&limit=1
[2024-05-01T15:51:06.685+0000] {taskinstance.py:441} INFO - ::group::Post task execution logs
[2024-05-01T15:51:06.686+0000] {taskinstance.py:2890} ERROR - Task failed with exception
Traceback (most recent call last):
  File "/home/airflow/.local/lib/python3.9/site-packages/urllib3/connectionpool.py", line 467, in _make_request
    self._validate_conn(conn)
  File "/home/airflow/.local/lib/python3.9/site-packages/urllib3/connectionpool.py", line 1099, in _validate_conn
    conn.connect()
  File "/home/airflow/.local/lib/python3.9/site-packages/urllib3/connection.py", line 653, in connect
    sock_and_verified = _ssl_wrap_socket_and_match_hostname(
  File "/home/airflow/.local/lib/python3.9/site-packages/urllib3/connection.py", line 806, in _ssl_wrap_socket_and_match_hostname
    ssl_sock = ssl_wrap_socket(
  File "/home/airflow/.local/lib/python3.9/site-packages/urllib3/util/ssl_.py", line 465, in ssl_wrap_socket
    ssl_sock = _ssl_wrap_socket_impl(sock, context, tls_in_tls, server_hostname)
  File "/home/airflow/.local/lib/python3.9/site-packages/urllib3/util/ssl_.py", line 509, in _ssl_wrap_socket_impl
    return ssl_context.wrap_socket(sock, server_hostname=server_hostname)
  File "/usr/local/lib/python3.9/ssl.py", line 501, in wrap_socket
    return self.sslsocket_class._create(
  File "/usr/local/lib/python3.9/ssl.py", line 1041, in _create
    self.do_handshake()
  File "/usr/local/lib/python3.9/ssl.py", line 1310, in do_handshake
    self._sslobj.do_handshake()
socket.timeout: _ssl.c:1112: The handshake operation timed out

The above exception was the direct cause of the following exception:

Traceback (most recent call last):
  File "/home/airflow/.local/lib/python3.9/site-packages/urllib3/connectionpool.py", line 793, in urlopen
    response = self._make_request(
  File "/home/airflow/.local/lib/python3.9/site-packages/urllib3/connectionpool.py", line 491, in _make_request
    raise new_e
  File "/home/airflow/.local/lib/python3.9/site-packages/urllib3/connectionpool.py", line 469, in _make_request
    self._raise_timeout(err=e, url=url, timeout_value=conn.timeout)
  File "/home/airflow/.local/lib/python3.9/site-packages/urllib3/connectionpool.py", line 370, in _raise_timeout
    raise ReadTimeoutError(
urllib3.exceptions.ReadTimeoutError: HTTPSConnectionPool(host='nominatim.openstreetmap.org', port=443): Read timed out. (read timeout=1)

The above exception was the direct cause of the following exception:

Traceback (most recent call last):
  File "/home/airflow/.local/lib/python3.9/site-packages/requests/adapters.py", line 486, in send
    resp = conn.urlopen(
  File "/home/airflow/.local/lib/python3.9/site-packages/urllib3/connectionpool.py", line 877, in urlopen
    return self.urlopen(
  File "/home/airflow/.local/lib/python3.9/site-packages/urllib3/connectionpool.py", line 877, in urlopen
    return self.urlopen(
  File "/home/airflow/.local/lib/python3.9/site-packages/urllib3/connectionpool.py", line 847, in urlopen
    retries = retries.increment(
  File "/home/airflow/.local/lib/python3.9/site-packages/urllib3/util/retry.py", line 515, in increment
    raise MaxRetryError(_pool, url, reason) from reason  # type: ignore[arg-type]
urllib3.exceptions.MaxRetryError: HTTPSConnectionPool(host='nominatim.openstreetmap.org', port=443): Max retries exceeded with url: /search?q=Stadio+Giuseppe+Meazza%2C+Italy&format=json&limit=1 (Caused by ReadTimeoutError("HTTPSConnectionPool(host='nominatim.openstreetmap.org', port=443): Read timed out. (read timeout=1)"))

During handling of the above exception, another exception occurred:

Traceback (most recent call last):
  File "/home/airflow/.local/lib/python3.9/site-packages/geopy/adapters.py", line 482, in _request
    resp = self.session.get(url, timeout=timeout, headers=headers)
  File "/home/airflow/.local/lib/python3.9/site-packages/requests/sessions.py", line 602, in get
    return self.request("GET", url, **kwargs)
  File "/home/airflow/.local/lib/python3.9/site-packages/requests/sessions.py", line 589, in request
    resp = self.send(prep, **send_kwargs)
  File "/home/airflow/.local/lib/python3.9/site-packages/requests/sessions.py", line 703, in send
    r = adapter.send(request, **kwargs)
  File "/home/airflow/.local/lib/python3.9/site-packages/requests/adapters.py", line 519, in send
    raise ConnectionError(e, request=request)
requests.exceptions.ConnectionError: HTTPSConnectionPool(host='nominatim.openstreetmap.org', port=443): Max retries exceeded with url: /search?q=Stadio+Giuseppe+Meazza%2C+Italy&format=json&limit=1 (Caused by ReadTimeoutError("HTTPSConnectionPool(host='nominatim.openstreetmap.org', port=443): Read timed out. (read timeout=1)"))

During handling of the above exception, another exception occurred:

Traceback (most recent call last):
  File "/home/airflow/.local/lib/python3.9/site-packages/airflow/models/taskinstance.py", line 465, in _execute_task
    result = _execute_callable(context=context, **execute_callable_kwargs)
  File "/home/airflow/.local/lib/python3.9/site-packages/airflow/models/taskinstance.py", line 432, in _execute_callable
    return execute_callable(context=context, **execute_callable_kwargs)
  File "/home/airflow/.local/lib/python3.9/site-packages/airflow/models/baseoperator.py", line 400, in wrapper
    return func(self, *args, **kwargs)
  File "/home/airflow/.local/lib/python3.9/site-packages/airflow/operators/python.py", line 235, in execute
    return_value = self.execute_callable()
  File "/home/airflow/.local/lib/python3.9/site-packages/airflow/operators/python.py", line 252, in execute_callable
    return self.python_callable(*self.op_args, **self.op_kwargs)
  File "/opt/airflow/pipelines/wikipedia_pipeline.py", line 88, in transform_wikipedia_data
    stadiums_df['location'] = stadiums_df.apply(lambda x: get_lat_long(x['country'], x['stadium']), axis = 1)
  File "/home/airflow/.local/lib/python3.9/site-packages/pandas/core/frame.py", line 10374, in apply
    return op.apply().__finalize__(self, method="apply")
  File "/home/airflow/.local/lib/python3.9/site-packages/pandas/core/apply.py", line 916, in apply
    return self.apply_standard()
  File "/home/airflow/.local/lib/python3.9/site-packages/pandas/core/apply.py", line 1063, in apply_standard
    results, res_index = self.apply_series_generator()
  File "/home/airflow/.local/lib/python3.9/site-packages/pandas/core/apply.py", line 1081, in apply_series_generator
    results[i] = self.func(v, *self.args, **self.kwargs)
  File "/opt/airflow/pipelines/wikipedia_pipeline.py", line 88, in <lambda>
    stadiums_df['location'] = stadiums_df.apply(lambda x: get_lat_long(x['country'], x['stadium']), axis = 1)
  File "/opt/airflow/pipelines/wikipedia_pipeline.py", line 74, in get_lat_long
    location = geolocator.geocode(f'{city}, {country}')
  File "/home/airflow/.local/lib/python3.9/site-packages/geopy/geocoders/nominatim.py", line 297, in geocode
    return self._call_geocoder(url, callback, timeout=timeout)
  File "/home/airflow/.local/lib/python3.9/site-packages/geopy/geocoders/base.py", line 368, in _call_geocoder
    result = self.adapter.get_json(url, timeout=timeout, headers=req_headers)
  File "/home/airflow/.local/lib/python3.9/site-packages/geopy/adapters.py", line 472, in get_json
    resp = self._request(url, timeout=timeout, headers=headers)
  File "/home/airflow/.local/lib/python3.9/site-packages/geopy/adapters.py", line 494, in _request
    raise GeocoderUnavailable(message)
geopy.exc.GeocoderUnavailable: HTTPSConnectionPool(host='nominatim.openstreetmap.org', port=443): Max retries exceeded with url: /search?q=Stadio+Giuseppe+Meazza%2C+Italy&format=json&limit=1 (Caused by ReadTimeoutError("HTTPSConnectionPool(host='nominatim.openstreetmap.org', port=443): Read timed out. (read timeout=1)"))
[2024-05-01T15:51:06.709+0000] {taskinstance.py:1205} INFO - Marking task as FAILED. dag_id=wikipedia_flow, task_id=transform_wikipedia_data, execution_date=20240501T154928, start_date=20240501T154939, end_date=20240501T155106
[2024-05-01T15:51:06.720+0000] {standard_task_runner.py:110} ERROR - Failed to execute job 14 for task transform_wikipedia_data (HTTPSConnectionPool(host='nominatim.openstreetmap.org', port=443): Max retries exceeded with url: /search?q=Stadio+Giuseppe+Meazza%2C+Italy&format=json&limit=1 (Caused by ReadTimeoutError("HTTPSConnectionPool(host='nominatim.openstreetmap.org', port=443): Read timed out. (read timeout=1)")); 3256)
[2024-05-01T15:51:06.739+0000] {local_task_job_runner.py:240} INFO - Task exited with return code 1
[2024-05-01T15:51:06.851+0000] {taskinstance.py:3482} INFO - 0 downstream tasks scheduled from follow-on schedule check
[2024-05-01T15:51:06.859+0000] {local_task_job_runner.py:222} INFO - ::endgroup::
